<?xml version="1.0" ?>
<!-- Generated using onshape-to-robot -->
<!-- Onshape document_id: 7d0d24259dc99910b3744602 -->
<robot name="output">
  <!-- Link base -->
  <link name="base">
    <inertial>
      <origin xyz="3.83001e-05 -2.40073e-05 0.0247678" rpy="0 0 0"/>
      <mass value="0.873654"/>
      <inertia ixx="0.00169404" ixy="2.44296e-07" ixz="-2.0408e-07" iyy="0.000678307" iyz="9.47541e-07" izz="0.00157059"/>
    </inertial>
    <!-- Part base -->
    <visual>
      <origin xyz="-0.0374966 -0.0464005 0.187501" rpy="1.15616e-19 1.5708 0"/>
      <geometry>
        <mesh filename="assets/base.stl"/>
      </geometry>
      <material name="base_material">
        <color rgba="0 0 0 1"/>
      </material>
    </visual>
    <collision>
      <origin xyz="-0.0374966 -0.0464005 0.187501" rpy="1.15616e-19 1.5708 0"/>
      <geometry>
        <mesh filename="assets/base.stl"/>
      </geometry>
    </collision>
  </link>
  <!-- Link link1 -->
  <link name="link1">
    <inertial>
      <origin xyz="-0.00261782 0.00744082 0.0237251" rpy="0 0 0"/>
      <mass value="0.104154"/>
      <inertia ixx="4.91898e-05" ixy="3.10838e-06" ixz="5.78638e-06" iyy="0.000129831" iyz="-1.38611e-05" izz="0.000118108"/>
    </inertial>
    <!-- Part link1 -->
    <visual>
      <origin xyz="-0.0464 0.0374968 0.119501" rpy="1.5708 1.5708 0"/>
      <geometry>
        <mesh filename="assets/link1.stl"/>
      </geometry>
      <material name="link1_material">
        <color rgba="0 0 0 1"/>
      </material>
    </visual>
    <collision>
      <origin xyz="-0.0464 0.0374968 0.119501" rpy="1.5708 1.5708 0"/>
      <geometry>
        <mesh filename="assets/link1.stl"/>
      </geometry>
    </collision>
  </link>
  <!-- Link link2 -->
  <link name="link2">
    <inertial>
      <origin xyz="0.129165 0.000134495 -0.0321253" rpy="0 0 0"/>
      <mass value="1.46908"/>
      <inertia ixx="0.00080009" ixy="-4.32984e-07" ixz="3.12562e-06" iyy="0.0146686" iyz="-1.11425e-08" izz="0.014599"/>
    </inertial>
    <!-- Part link2 -->
    <visual>
      <origin xyz="-0.0174977 -0.0740001 -0.07925" rpy="1.5708 -3.58252e-15 1.5708"/>
      <geometry>
        <mesh filename="assets/link2.stl"/>
      </geometry>
      <material name="link2_material">
        <color rgba="1 1 1 1"/>
      </material>
    </visual>
    <collision>
      <origin xyz="-0.0174977 -0.0740001 -0.07925" rpy="1.5708 -3.58252e-15 1.5708"/>
      <geometry>
        <mesh filename="assets/link2.stl"/>
      </geometry>
    </collision>
  </link>
  <!-- Link link3 -->
  <link name="link3">
    <inertial>
      <origin xyz="0.0556042 -0.135083 -0.0340514" rpy="0 0 0"/>
      <mass value="0.982553"/>
      <inertia ixx="0.00758945" ixy="0.00064069" ixz="-4.36075e-06" iyy="0.000937606" iyz="-1.09983e-05" izz="0.00763097"/>
    </inertial>
    <!-- Part link3 -->
    <visual>
      <origin xyz="0.0740003 -0.281499 -0.0813" rpy="1.5708 -4.54273e-15 -3.14159"/>
      <geometry>
        <mesh filename="assets/link3.stl"/>
      </geometry>
      <material name="link3_material">
        <color rgba="1 1 1 1"/>
      </material>
    </visual>
    <collision>
      <origin xyz="0.0740003 -0.281499 -0.0813" rpy="1.5708 -4.54273e-15 -3.14159"/>
      <geometry>
        <mesh filename="assets/link3.stl"/>
      </geometry>
    </collision>
  </link>
  <!-- Link link4 -->
  <link name="link4">
    <inertial>
      <origin xyz="-0.0543529 0.057068 -0.0332231" rpy="0 0 0"/>
      <mass value="0.46678"/>
      <inertia ixx="0.000490786" ixy="0.000251119" ixz="2.1478e-05" iyy="0.000624073" iyz="-2.15661e-05" izz="0.000790045"/>
    </inertial>
    <!-- Part link4 -->
    <visual>
      <origin xyz="-0.0138003 0.0364989 -0.0787882" rpy="1.5708 -1.57772e-30 -1.26578e-30"/>
      <geometry>
        <mesh filename="assets/link4.stl"/>
      </geometry>
      <material name="link4_material">
        <color rgba="0 0 0 1"/>
      </material>
    </visual>
    <collision>
      <origin xyz="-0.0138003 0.0364989 -0.0787882" rpy="1.5708 -1.57772e-30 -1.26578e-30"/>
      <geometry>
        <mesh filename="assets/link4.stl"/>
      </geometry>
    </collision>
  </link>
  <!-- Link link5 -->
  <link name="link5">
    <inertial>
      <origin xyz="-3.55003e-05 -0.00717397 0.0375847" rpy="0 0 0"/>
      <mass value="0.403307"/>
      <inertia ixx="0.000219791" ixy="-3.49657e-07" ixz="2.10549e-07" iyy="0.000181053" iyz="1.29173e-05" izz="0.000184284"/>
    </inertial>
    <!-- Part link5 -->
    <visual>
      <origin xyz="-0.0463995 0.0311519 0.0265" rpy="-1.5708 -1.5708 0"/>
      <geometry>
        <mesh filename="assets/link5.stl"/>
      </geometry>
      <material name="link5_material">
        <color rgba="0 0 0 1"/>
      </material>
    </visual>
    <collision>
      <origin xyz="-0.0463995 0.0311519 0.0265" rpy="-1.5708 -1.5708 0"/>
      <geometry>
        <mesh filename="assets/link5.stl"/>
      </geometry>
    </collision>
  </link>
  <!-- Link gripper -->
  <link name="gripper">
    <inertial>
      <origin xyz="-3.57066e-05 0.000249371 -0.0293133" rpy="0 0 0"/>
      <mass value="0.553219"/>
      <inertia ixx="0.000409668" ixy="5.44942e-07" ixz="7.91266e-07" iyy="0.000324942" iyz="-4.83958e-06" izz="0.000369249"/>
    </inertial>
    <!-- Part gripper -->
    <visual>
      <origin xyz="-0.014 -0.0463995 0.0731" rpy="-2.40808e-14 1.46014e-15 -3.15544e-30"/>
      <geometry>
        <mesh filename="assets/gripper.stl"/>
      </geometry>
      <material name="gripper_material">
        <color rgba="0 0 0 1"/>
      </material>
    </visual>
    <collision>
      <origin xyz="-0.014 -0.0463995 0.0731" rpy="-2.40808e-14 1.46014e-15 -3.15544e-30"/>
      <geometry>
        <mesh filename="assets/gripper.stl"/>
      </geometry>
    </collision>
  </link>
  <!-- Link tip_left -->
  <link name="tip_left">
    <inertial>
      <origin xyz="-0.0224716 0.0143408 -0.0426253" rpy="0 0 0"/>
      <mass value="0.0710042"/>
      <inertia ixx="4.82351e-05" ixy="1.03366e-05" ixz="-1.13904e-05" iyy="5.1953e-05" iyz="1.10487e-05" izz="5.06981e-05"/>
    </inertial>
    <!-- Part tip_left -->
    <visual>
      <origin xyz="0.129783 0.00999321 -0.0914614" rpy="1.5708 -6.86541e-15 1.5708"/>
      <geometry>
        <mesh filename="assets/tip_left.stl"/>
      </geometry>
      <material name="tip_left_material">
        <color rgba="0 0 0 1"/>
      </material>
    </visual>
    <collision>
      <origin xyz="0.129783 0.00999321 -0.0914614" rpy="1.5708 -6.86541e-15 1.5708"/>
      <geometry>
        <mesh filename="assets/tip_left.stl"/>
      </geometry>
    </collision>
  </link>
  <!-- Joint from gripper to tip_left -->
  <joint name="joint7" type="prismatic">
    <origin xyz="-0.0226681 0.0450619 -0.0545599" rpy="-1.5708 -1.5708 0"/>
    <parent link="gripper"/>
    <child link="tip_left"/>
    <axis xyz="0 0 1"/>
    <limit effort="10" velocity="10" lower="-0.0475" upper="0"/>
  </joint>
  <!-- Link tip_right -->
  <link name="tip_right">
    <inertial>
      <origin xyz="-0.0143408 -0.0224716 -0.0426253" rpy="0 0 0"/>
      <mass value="0.0710042"/>
      <inertia ixx="5.1953e-05" ixy="-1.03366e-05" ixz="-1.10487e-05" iyy="4.82351e-05" iyz="-1.13904e-05" izz="5.06981e-05"/>
    </inertial>
    <!-- Part tip_right -->
    <visual>
      <origin xyz="-0.0379932 0.129783 0.00133753" rpy="-1.5708 6.86541e-15 -1.39661e-30"/>
      <geometry>
        <mesh filename="assets/tip_right.stl"/>
      </geometry>
      <material name="tip_right_material">
        <color rgba="0 0 0 1"/>
      </material>
    </visual>
    <collision>
      <origin xyz="-0.0379932 0.129783 0.00133753" rpy="-1.5708 6.86541e-15 -1.39661e-30"/>
      <geometry>
        <mesh filename="assets/tip_right.stl"/>
      </geometry>
    </collision>
  </link>
  <!-- Joint from gripper to tip_right -->
  <joint name="joint8" type="prismatic">
    <origin xyz="0.0226681 -0.0450619 -0.0545599" rpy="1.5708 3.37031e-15 -1.44357e-14"/>
    <parent link="gripper"/>
    <child link="tip_right"/>
    <axis xyz="0 0 1"/>
    <limit effort="10" velocity="10" lower="-0.0475" upper="0"/>
  </joint>
  <!-- Joint from link5 to gripper -->
  <joint name="joint6" type="revolute">
    <origin xyz="2.39858e-07 -0.0419481 0.0404996" rpy="-1.5708 -1.5708 0"/>
    <parent link="link5"/>
    <child link="gripper"/>
    <axis xyz="0 0 1"/>
    <limit effort="10" velocity="10" lower="-2.0944" upper="2.0944"/>
  </joint>
  <!-- Joint from link4 to link5 -->
  <joint name="joint5" type="revolute">
    <origin xyz="-0.0403003 0.0703851 -0.0323887" rpy="-3.14159 -1.5708 0"/>
    <parent link="link4"/>
    <child link="link5"/>
    <axis xyz="0 0 1"/>
    <limit effort="10" velocity="10" lower="-1.5708" upper="1.5708"/>
  </joint>
  <!-- Joint from link3 to link4 -->
  <joint name="joint4" type="revolute">
    <origin xyz="0.0600003 -0.244999 -0.00205" rpy="-1.4667e-14 -1.70957e-14 -3.14159"/>
    <parent link="link3"/>
    <child link="link4"/>
    <axis xyz="0 0 1"/>
    <limit effort="10" velocity="10" lower="-1.5708" upper="1.5708"/>
  </joint>
  <!-- Joint from link2 to link3 -->
  <joint name="joint3" type="revolute">
    <origin xyz="0.264 4.08431e-07 -0.06375" rpy="-3.14159 6.51959e-15 1.5708"/>
    <parent link="link2"/>
    <child link="link3"/>
    <axis xyz="0 0 1"/>
    <limit effort="10" velocity="10" lower="0" upper="3.66519"/>
  </joint>
  <!-- Joint from link1 to link2 -->
  <joint name="joint2" type="revolute">
    <origin xyz="-0.0329 0.02 0.0455" rpy="1.5708 -5.36072e-16 -1.5708"/>
    <parent link="link1"/>
    <child link="link2"/>
    <axis xyz="0 0 1"/>
    <limit effort="10" velocity="10" lower="0" upper="3.14159"/>
  </joint>
  <!-- Joint from base to link1 -->
  <joint name="joint1" type="revolute">
    <origin xyz="-1.249e-16 -1.38692e-16 0.067" rpy="4.43651e-16 -1.15412e-16 -1.5708"/>
    <parent link="base"/>
    <child link="link1"/>
    <axis xyz="0 0 1"/>
    <limit effort="10" velocity="10" lower="-2.61799" upper="3.05433"/>
  </joint>
</robot>
